<?xml version="1.0"?>
<robot name="robot" xmlns:xacro="http://www.ros.org/wiki/xacro" >

 <material name="blue">
 	<color rgba="0 0 0.8 1"/>
 </material>

 <material name="white">
	 <color rgba="1 1 1 1"/>
 </material>

 <xacro:property name="m" value="0.3" />
 <xacro:property name="l1" value="0.2" />		
 <xacro:property name="b1" value="0.1" />		
 <xacro:property name="h1" value="0.02" />


 <xacro:property name="b2" value="0.2" />		
 <xacro:property name="h2" value="0.005" />				


	<link name="chassis">
		<pose>0 0 0.1 0 0 0</pose>
		<visual>
			<origin rpy="0 0 0" xyz="0 0 0"/>
			<geometry>
					<box size="${l1} ${b1} ${h1}"/>
			</geometry>
			<material name="blue"/>
		</visual>
		
		<visual>
			<origin rpy="1.5707 0 1.5707" xyz="${l1/2 - h2/2} 0 ${b2/2}"/>
			<geometry>
					<box size="${b1} ${b2} ${h2}"/>
			</geometry>
			<material name="blue"/>
		</visual>
	
		<visual>
			<origin rpy="1.5707 0 1.5707" xyz="-${l1/2 - h2/2} 0 ${b2/2}"/>
			<geometry>
					<box size="${b1} ${b2} ${h2}"/>
			</geometry>
			<material name="blue"/>
		</visual>
		
		<visual>
			<origin rpy="0 0 0" xyz="0 0 ${b2+h1/2}"/>
			<geometry>
					<box size="${l1} ${b1} ${h1}"/>
			</geometry>
			<material name="blue"/>
		</visual>
		
		<collision name="collision_chassis">
			<geometry>
				<box size="${l1} ${b1} ${h1}"/>
			</geometry>
		</collision>

		<inertial>
			<mass value="${m}"/>
			<origin rpy="0 0 0" xyz="0 0 ${b2/2+h1}"/>
			<inertia ixx="${2*m*h1*b1/12.0}" ixy="0" ixz="0" iyy="${2*m*l1*h1/12.0}" iyz="0" izz="${2*m*l1*b1/12.0}"/>
		</inertial>
	</link>


	<!--    wheels     -->

 <xacro:property name="l3" value="0.02" />		
 <xacro:property name="r3" value="0.06" />
 <xacro:property name="m3" value="0.05" />

	<link name="right_wheel">
		<visual>
			<origin rpy="0 1.5707 0" xyz="0 0 0"/>
			<geometry>
					<cylinder length="${l3}" radius="${r3}"/>
			</geometry>
			<material name="white"/>
		</visual>

		<collision name="collision_right_wheel">
		<origin rpy="0 1.5707 1.5707" xyz="0 0 0"/>
			<geometry>
				<cylinder length="${l3}" radius="${r3}"/>
			</geometry>
		</collision>

		<inertial>
			<mass value="0.2"/>
			<origin rpy="0 1.5707 1.5707" xyz="0 0 0"/>
			<inertia ixx="${m3*((3*r3*r3)+(l3*l3))/12.0}" ixy="0" ixz="0" iyy="${m3*((3*r3*r3)+(l3*l3))/12.0}" iyz="0" izz="${(m3*r3*r3)/2.0}"/>
		</inertial>
	</link>

	<joint name="joint_right_wheel_chassis" type="continuous">
		<origin rpy="0 0 0" xyz="${l1/2+l3/2} 0 0"/>
		<child link="right_wheel"/>
		<parent link="chassis"/>
		<axis xyz="1 0 0"/>
		<limit effort="10000" velocity="1000"/>
		<joint_properties damping="1.0" friction="1.0"/>
	</joint>
	

	<link name="left_wheel">
		<visual>
			<origin rpy="0 1.5707 0" xyz="0 0 0"/>
			<geometry>
					<cylinder length="${l3}" radius="${r3}"/>
			</geometry>
			<material name="white"/>
		</visual>

		<collision name="collision_left_wheel">
		<origin rpy="0 1.5707 1.5707" xyz="0 0 0"/>
			<geometry>
				<cylinder length="${l3}" radius="${r3}"/>
			</geometry>
		</collision>

		<inertial>
			<mass value="0.2"/>
			<origin rpy="0 1.5707 1.5707" xyz="0 0 0"/>
			<inertia ixx="${m3*((3*r3*r3)+(l3*l3))/12.0}" ixy="0" ixz="0" iyy="${m3*((3*r3*r3)+(l3*l3))/12.0}" iyz="0" izz="${(m3*r3*r3)/2.0}"/>
		</inertial>
	</link>	
	
	<joint name="joint_left_wheel_chassis" type="continuous">
		<origin rpy="0 0 0" xyz="-${l1/2+l3/2} 0 0"/>
		<child link="left_wheel"/>
		<parent link="chassis"/>
		<axis xyz="1 0 0"/>
		<limit effort="10000" velocity="1000"/>
		<joint_properties damping="1.0" friction="1.0"/>
	</joint>
</robot>
